<mujoco>
  <worldbody>
    <body pos="0 5.13 0.75" quat="-1 0 0 0" gravcomp="0" name="torso_0">
      <freejoint name="root_1" />
      <geom density="5" type="sphere" size="0.25" pos="0 0 0" quat="-1 0 0 0" priority="0" contype="1" conaffinity="0" group="0" condim="3" solmix="1" solref="0.02 1" solimp="0.9 0.95 0.001" margin="0.01" gap="0" friction="1 0.5 0.5" fluidshape="none" fluidcoef="5 0.25 1.5 1 1" name="torso_geom_2" />
      <body pos="0 0 0" quat="-1 0 0 0" gravcomp="0" name="front_left_leg_3">
        <geom density="5" type="capsule" size="0.08000002 0.141421" pos="0.1 0.0999999 0" quat="0.7071069 0.4999999 -0.4999999 0" priority="0" contype="1" conaffinity="0" group="0" condim="3" solmix="1" solref="0.02 1" solimp="0.9 0.95 0.001" margin="0.01" gap="0" friction="1 0.5 0.5" fluidshape="none" fluidcoef="5 0.25 1.5 1 1" name="aux_1_geom_7" />
        <body pos="0.2 0.1999998 0" quat="-1 0 0 0" gravcomp="0" name="aux_1_8">
          <joint type="hinge" pos="0 0 0" axis="-1.192093E-07 0 1" ref="0" armature="1" springref="0" springdamper="0 0" damping="1" stiffness="0" solreflimit="0.02 1" solimplimit="0.9 0.95 0.001 0.5 2" solreffriction="0.02 1" solimpfriction="0.9 0.95 0.001 0.5 2" frictionloss="0" limited="true" margin="0" range="-30.00002 30.00002" name="hip_1_15" />
          <geom density="5" type="capsule" size="0.08000002 0.141421" pos="0.1 0.1000004 0" quat="0.7071069 0.4999999 -0.4999999 0" priority="0" contype="1" conaffinity="0" group="0" condim="3" solmix="1" solref="0.02 1" solimp="0.9 0.95 0.001" margin="0.01" gap="0" friction="1 0.5 0.5" fluidshape="none" fluidcoef="5 0.25 1.5 1 1" name="left_leg_geom_16" />
          <body pos="0.2 0.2000003 0" quat="-1 0 0 0" gravcomp="0" name="body_0_17">
            <joint type="hinge" pos="0 0 0" axis="-0.7071069 0.7071068 0" ref="0" armature="1" springref="0" springdamper="0 0" damping="1" stiffness="0" solreflimit="0.02 1" solimplimit="0.9 0.95 0.001 0.5 2" solreffriction="0.02 1" solimpfriction="0.9 0.95 0.001 0.5 2" frictionloss="0" limited="true" margin="0" range="30.00002 69.99997" name="ankle_1_27" />
            <geom density="5" type="capsule" size="0.08000002 0.2828431" pos="0.2 0.1999998 0" quat="0.7071069 0.4999999 -0.4999999 0" priority="0" contype="1" conaffinity="0" group="0" condim="3" solmix="1" solref="0.02 1" solimp="0.9 0.95 0.001" margin="0.01" gap="0" friction="1 0.5 0.5" fluidshape="none" fluidcoef="5 0.25 1.5 1 1" name="left_ankle_geom_28" />
          </body>
        </body>
      </body>
      <body pos="0 0 0" quat="-1 0 0 0" gravcomp="0" name="front_right_leg_4">
        <geom density="5" type="capsule" size="0.08000002 0.141421" pos="-0.1 0.0999999 0" quat="0.7071069 0.4999999 0.4999999 0" priority="0" contype="1" conaffinity="0" group="0" condim="3" solmix="1" solref="0.02 1" solimp="0.9 0.95 0.001" margin="0.01" gap="0" friction="1 0.5 0.5" fluidshape="none" fluidcoef="5 0.25 1.5 1 1" name="aux_2_geom_9" />
        <body pos="-0.2 0.1999998 0" quat="-1 0 0 0" gravcomp="0" name="aux_2_10">
          <joint type="hinge" pos="0 0 0" axis="-1.192093E-07 0 1" ref="0" armature="1" springref="0" springdamper="0 0" damping="1" stiffness="0" solreflimit="0.02 1" solimplimit="0.9 0.95 0.001 0.5 2" solreffriction="0.02 1" solimpfriction="0.9 0.95 0.001 0.5 2" frictionloss="0" limited="true" margin="0" range="-30.00002 30.00002" name="hip_2_18" />
          <geom density="5" type="capsule" size="0.08000002 0.141421" pos="-0.1 0.1000004 0" quat="0.7071069 0.4999999 0.4999999 0" priority="0" contype="1" conaffinity="0" group="0" condim="3" solmix="1" solref="0.02 1" solimp="0.9 0.95 0.001" margin="0.01" gap="0" friction="1 0.5 0.5" fluidshape="none" fluidcoef="5 0.25 1.5 1 1" name="right_leg_geom_19" />
          <body pos="-0.2 0.2000003 0" quat="-1 0 0 0" gravcomp="0" name="body_1_20">
            <joint type="hinge" pos="0 0 0" axis="0.7071067 0.7071068 0" ref="0" armature="1" springref="0" springdamper="0 0" damping="1" stiffness="0" solreflimit="0.02 1" solimplimit="0.9 0.95 0.001 0.5 2" solreffriction="0.02 1" solimpfriction="0.9 0.95 0.001 0.5 2" frictionloss="0" limited="true" margin="0" range="-69.99997 -30.00002" name="ankle_2_29" />
            <geom density="5" type="capsule" size="0.08000002 0.2828431" pos="-0.2 0.1999998 0" quat="0.7071069 0.4999999 0.4999999 0" priority="0" contype="1" conaffinity="0" group="0" condim="3" solmix="1" solref="0.02 1" solimp="0.9 0.95 0.001" margin="0.01" gap="0" friction="1 0.5 0.5" fluidshape="none" fluidcoef="5 0.25 1.5 1 1" name="right_ankle_geom_30" />
          </body>
        </body>
      </body>
      <body pos="0 0 0" quat="-1 0 0 0" gravcomp="0" name="back_leg_5">
        <geom density="5" type="capsule" size="0.08000002 0.141421" pos="-0.1 -0.0999999 0" quat="0.7071069 -0.4999999 0.4999999 0" priority="0" contype="1" conaffinity="0" group="0" condim="3" solmix="1" solref="0.02 1" solimp="0.9 0.95 0.001" margin="0.01" gap="0" friction="1 0.5 0.5" fluidshape="none" fluidcoef="5 0.25 1.5 1 1" name="aux_3_geom_11" />
        <body pos="-0.2 -0.1999998 0" quat="-1 0 0 0" gravcomp="0" name="aux_3_12">
          <joint type="hinge" pos="0 0 0" axis="-1.192093E-07 0 1" ref="0" armature="1" springref="0" springdamper="0 0" damping="1" stiffness="0" solreflimit="0.02 1" solimplimit="0.9 0.95 0.001 0.5 2" solreffriction="0.02 1" solimpfriction="0.9 0.95 0.001 0.5 2" frictionloss="0" limited="true" margin="0" range="-30.00002 30.00002" name="hip_3_21" />
          <geom density="5" type="capsule" size="0.08000002 0.141421" pos="-0.1 -0.1000004 0" quat="0.7071069 -0.4999999 0.4999999 0" priority="0" contype="1" conaffinity="0" group="0" condim="3" solmix="1" solref="0.02 1" solimp="0.9 0.95 0.001" margin="0.01" gap="0" friction="1 0.5 0.5" fluidshape="none" fluidcoef="5 0.25 1.5 1 1" name="back_leg_geom_22" />
          <body pos="-0.2 -0.2000003 0" quat="-1 0 0 0" gravcomp="0" name="body_2_23">
            <joint type="hinge" pos="0 0 0" axis="-0.7071069 0.7071068 0" ref="0" armature="1" springref="0" springdamper="0 0" damping="1" stiffness="0" solreflimit="0.02 1" solimplimit="0.9 0.95 0.001 0.5 2" solreffriction="0.02 1" solimpfriction="0.9 0.95 0.001 0.5 2" frictionloss="0" limited="true" margin="0" range="-69.99997 -30.00002" name="ankle_3_31" />
            <geom density="5" type="capsule" size="0.08000002 0.2828431" pos="-0.2 -0.1999998 0" quat="0.7071069 -0.4999999 0.4999999 0" priority="0" contype="1" conaffinity="0" group="0" condim="3" solmix="1" solref="0.02 1" solimp="0.9 0.95 0.001" margin="0.01" gap="0" friction="1 0.5 0.5" fluidshape="none" fluidcoef="5 0.25 1.5 1 1" name="third_ankle_geom_32" />
          </body>
        </body>
      </body>
      <body pos="0 0 0" quat="-1 0 0 0" gravcomp="0" name="right_back_leg_6">
        <geom density="5" type="capsule" size="0.08000002 0.141421" pos="0.1 -0.0999999 0" quat="0.7071069 -0.4999999 -0.4999999 0" priority="0" contype="1" conaffinity="0" group="0" condim="3" solmix="1" solref="0.02 1" solimp="0.9 0.95 0.001" margin="0.01" gap="0" friction="1 0.5 0.5" fluidshape="none" fluidcoef="5 0.25 1.5 1 1" name="aux_4_geom_13" />
        <body pos="0.2 -0.1999998 0" quat="-1 0 0 0" gravcomp="0" name="aux_4_14">
          <joint type="hinge" pos="0 0 0" axis="-1.192093E-07 0 1" ref="0" armature="1" springref="0" springdamper="0 0" damping="1" stiffness="0" solreflimit="0.02 1" solimplimit="0.9 0.95 0.001 0.5 2" solreffriction="0.02 1" solimpfriction="0.9 0.95 0.001 0.5 2" frictionloss="0" limited="true" margin="0" range="-30.00002 30.00002" name="hip_4_24" />
          <geom density="5" type="capsule" size="0.08000002 0.141421" pos="0.1 -0.1000004 0" quat="0.7071069 -0.4999999 -0.4999999 0" priority="0" contype="1" conaffinity="0" group="0" condim="3" solmix="1" solref="0.02 1" solimp="0.9 0.95 0.001" margin="0.01" gap="0" friction="1 0.5 0.5" fluidshape="none" fluidcoef="5 0.25 1.5 1 1" name="rightback_leg_geom_25" />
          <body pos="0.2 -0.2000003 0" quat="-1 0 0 0" gravcomp="0" name="body_3_26">
            <joint type="hinge" pos="0 0 0" axis="0.7071067 0.7071068 0" ref="0" armature="1" springref="0" springdamper="0 0" damping="1" stiffness="0" solreflimit="0.02 1" solimplimit="0.9 0.95 0.001 0.5 2" solreffriction="0.02 1" solimpfriction="0.9 0.95 0.001 0.5 2" frictionloss="0" limited="true" margin="0" range="30.00002 69.99997" name="ankle_4_33" />
            <geom density="5" type="capsule" size="0.08000002 0.2828431" pos="0.2 -0.1999998 0" quat="0.7071069 -0.4999999 -0.4999999 0" priority="0" contype="1" conaffinity="0" group="0" condim="3" solmix="1" solref="0.02 1" solimp="0.9 0.95 0.001" margin="0.01" gap="0" friction="1 0.5 0.5" fluidshape="none" fluidcoef="5 0.25 1.5 1 1" name="fourth_ankle_geom_34" />
          </body>
        </body>
      </body>
    </body>
    <body pos="0 0 0.75" quat="-1 0 0 0" gravcomp="0" name="torso_35">
      <freejoint name="root_36" />
      <geom density="5" type="sphere" size="0.25" pos="0 0 0" quat="-1 0 0 0" priority="0" contype="1" conaffinity="0" group="0" condim="3" solmix="1" solref="0.02 1" solimp="0.9 0.95 0.001" margin="0.01" gap="0" friction="1 0.5 0.5" fluidshape="none" fluidcoef="5 0.25 1.5 1 1" name="torso_geom_37" />
      <body pos="0 0 0" quat="-1 0 0 0" gravcomp="0" name="front_left_leg_38">
        <geom density="5" type="capsule" size="0.08000002 0.141421" pos="0.1 0.1 0" quat="0.7071069 0.4999999 -0.4999999 0" priority="0" contype="1" conaffinity="0" group="0" condim="3" solmix="1" solref="0.02 1" solimp="0.9 0.95 0.001" margin="0.01" gap="0" friction="1 0.5 0.5" fluidshape="none" fluidcoef="5 0.25 1.5 1 1" name="aux_1_geom_42" />
        <body pos="0.2 0.2 0" quat="-1 0 0 0" gravcomp="0" name="aux_1_43">
          <joint type="hinge" pos="0 0 0" axis="-1.192093E-07 0 1" ref="0" armature="1" springref="0" springdamper="0 0" damping="1" stiffness="0" solreflimit="0.02 1" solimplimit="0.9 0.95 0.001 0.5 2" solreffriction="0.02 1" solimpfriction="0.9 0.95 0.001 0.5 2" frictionloss="0" limited="true" margin="0" range="-30.00002 30.00002" name="hip_1_50" />
          <geom density="5" type="capsule" size="0.08000002 0.141421" pos="0.1 0.1 0" quat="0.7071069 0.4999999 -0.4999999 0" priority="0" contype="1" conaffinity="0" group="0" condim="3" solmix="1" solref="0.02 1" solimp="0.9 0.95 0.001" margin="0.01" gap="0" friction="1 0.5 0.5" fluidshape="none" fluidcoef="5 0.25 1.5 1 1" name="left_leg_geom_51" />
          <body pos="0.2 0.2 0" quat="-1 0 0 0" gravcomp="0" name="body_0_52">
            <joint type="hinge" pos="0 0 0" axis="-0.7071069 0.7071068 0" ref="0" armature="1" springref="0" springdamper="0 0" damping="1" stiffness="0" solreflimit="0.02 1" solimplimit="0.9 0.95 0.001 0.5 2" solreffriction="0.02 1" solimpfriction="0.9 0.95 0.001 0.5 2" frictionloss="0" limited="true" margin="0" range="30.00002 69.99997" name="ankle_1_62" />
            <geom density="5" type="capsule" size="0.08000002 0.2828431" pos="0.2 0.2 0" quat="0.7071069 0.4999999 -0.4999999 0" priority="0" contype="1" conaffinity="0" group="0" condim="3" solmix="1" solref="0.02 1" solimp="0.9 0.95 0.001" margin="0.01" gap="0" friction="1 0.5 0.5" fluidshape="none" fluidcoef="5 0.25 1.5 1 1" name="left_ankle_geom_63" />
          </body>
        </body>
      </body>
      <body pos="0 0 0" quat="-1 0 0 0" gravcomp="0" name="front_right_leg_39">
        <geom density="5" type="capsule" size="0.08000002 0.141421" pos="-0.1 0.1 0" quat="0.7071069 0.4999999 0.4999999 0" priority="0" contype="1" conaffinity="0" group="0" condim="3" solmix="1" solref="0.02 1" solimp="0.9 0.95 0.001" margin="0.01" gap="0" friction="1 0.5 0.5" fluidshape="none" fluidcoef="5 0.25 1.5 1 1" name="aux_2_geom_44" />
        <body pos="-0.2 0.2 0" quat="-1 0 0 0" gravcomp="0" name="aux_2_45">
          <joint type="hinge" pos="0 0 0" axis="-1.192093E-07 0 1" ref="0" armature="1" springref="0" springdamper="0 0" damping="1" stiffness="0" solreflimit="0.02 1" solimplimit="0.9 0.95 0.001 0.5 2" solreffriction="0.02 1" solimpfriction="0.9 0.95 0.001 0.5 2" frictionloss="0" limited="true" margin="0" range="-30.00002 30.00002" name="hip_2_53" />
          <geom density="5" type="capsule" size="0.08000002 0.141421" pos="-0.1 0.1 0" quat="0.7071069 0.4999999 0.4999999 0" priority="0" contype="1" conaffinity="0" group="0" condim="3" solmix="1" solref="0.02 1" solimp="0.9 0.95 0.001" margin="0.01" gap="0" friction="1 0.5 0.5" fluidshape="none" fluidcoef="5 0.25 1.5 1 1" name="right_leg_geom_54" />
          <body pos="-0.2 0.2 0" quat="-1 0 0 0" gravcomp="0" name="body_1_55">
            <joint type="hinge" pos="0 0 0" axis="0.7071067 0.7071068 0" ref="0" armature="1" springref="0" springdamper="0 0" damping="1" stiffness="0" solreflimit="0.02 1" solimplimit="0.9 0.95 0.001 0.5 2" solreffriction="0.02 1" solimpfriction="0.9 0.95 0.001 0.5 2" frictionloss="0" limited="true" margin="0" range="-69.99997 -30.00002" name="ankle_2_64" />
            <geom density="5" type="capsule" size="0.08000002 0.2828431" pos="-0.2 0.2 0" quat="0.7071069 0.4999999 0.4999999 0" priority="0" contype="1" conaffinity="0" group="0" condim="3" solmix="1" solref="0.02 1" solimp="0.9 0.95 0.001" margin="0.01" gap="0" friction="1 0.5 0.5" fluidshape="none" fluidcoef="5 0.25 1.5 1 1" name="right_ankle_geom_65" />
          </body>
        </body>
      </body>
      <body pos="0 0 0" quat="-1 0 0 0" gravcomp="0" name="back_leg_40">
        <geom density="5" type="capsule" size="0.08000002 0.141421" pos="-0.1 -0.1 0" quat="0.7071069 -0.4999999 0.4999999 0" priority="0" contype="1" conaffinity="0" group="0" condim="3" solmix="1" solref="0.02 1" solimp="0.9 0.95 0.001" margin="0.01" gap="0" friction="1 0.5 0.5" fluidshape="none" fluidcoef="5 0.25 1.5 1 1" name="aux_3_geom_46" />
        <body pos="-0.2 -0.2 0" quat="-1 0 0 0" gravcomp="0" name="aux_3_47">
          <joint type="hinge" pos="0 0 0" axis="-1.192093E-07 0 1" ref="0" armature="1" springref="0" springdamper="0 0" damping="1" stiffness="0" solreflimit="0.02 1" solimplimit="0.9 0.95 0.001 0.5 2" solreffriction="0.02 1" solimpfriction="0.9 0.95 0.001 0.5 2" frictionloss="0" limited="true" margin="0" range="-30.00002 30.00002" name="hip_3_56" />
          <geom density="5" type="capsule" size="0.08000002 0.141421" pos="-0.1 -0.1 0" quat="0.7071069 -0.4999999 0.4999999 0" priority="0" contype="1" conaffinity="0" group="0" condim="3" solmix="1" solref="0.02 1" solimp="0.9 0.95 0.001" margin="0.01" gap="0" friction="1 0.5 0.5" fluidshape="none" fluidcoef="5 0.25 1.5 1 1" name="back_leg_geom_57" />
          <body pos="-0.2 -0.2 0" quat="-1 0 0 0" gravcomp="0" name="body_2_58">
            <joint type="hinge" pos="0 0 0" axis="-0.7071069 0.7071068 0" ref="0" armature="1" springref="0" springdamper="0 0" damping="1" stiffness="0" solreflimit="0.02 1" solimplimit="0.9 0.95 0.001 0.5 2" solreffriction="0.02 1" solimpfriction="0.9 0.95 0.001 0.5 2" frictionloss="0" limited="true" margin="0" range="-69.99997 -30.00002" name="ankle_3_66" />
            <geom density="5" type="capsule" size="0.08000002 0.2828431" pos="-0.2 -0.2 0" quat="0.7071069 -0.4999999 0.4999999 0" priority="0" contype="1" conaffinity="0" group="0" condim="3" solmix="1" solref="0.02 1" solimp="0.9 0.95 0.001" margin="0.01" gap="0" friction="1 0.5 0.5" fluidshape="none" fluidcoef="5 0.25 1.5 1 1" name="third_ankle_geom_67" />
          </body>
        </body>
      </body>
      <body pos="0 0 0" quat="-1 0 0 0" gravcomp="0" name="right_back_leg_41">
        <geom density="5" type="capsule" size="0.08000002 0.141421" pos="0.1 -0.1 0" quat="0.7071069 -0.4999999 -0.4999999 0" priority="0" contype="1" conaffinity="0" group="0" condim="3" solmix="1" solref="0.02 1" solimp="0.9 0.95 0.001" margin="0.01" gap="0" friction="1 0.5 0.5" fluidshape="none" fluidcoef="5 0.25 1.5 1 1" name="aux_4_geom_48" />
        <body pos="0.2 -0.2 0" quat="-1 0 0 0" gravcomp="0" name="aux_4_49">
          <joint type="hinge" pos="0 0 0" axis="-1.192093E-07 0 1" ref="0" armature="1" springref="0" springdamper="0 0" damping="1" stiffness="0" solreflimit="0.02 1" solimplimit="0.9 0.95 0.001 0.5 2" solreffriction="0.02 1" solimpfriction="0.9 0.95 0.001 0.5 2" frictionloss="0" limited="true" margin="0" range="-30.00002 30.00002" name="hip_4_59" />
          <geom density="5" type="capsule" size="0.08000002 0.141421" pos="0.1 -0.1 0" quat="0.7071069 -0.4999999 -0.4999999 0" priority="0" contype="1" conaffinity="0" group="0" condim="3" solmix="1" solref="0.02 1" solimp="0.9 0.95 0.001" margin="0.01" gap="0" friction="1 0.5 0.5" fluidshape="none" fluidcoef="5 0.25 1.5 1 1" name="rightback_leg_geom_60" />
          <body pos="0.2 -0.2 0" quat="-1 0 0 0" gravcomp="0" name="body_3_61">
            <joint type="hinge" pos="0 0 0" axis="0.7071067 0.7071068 0" ref="0" armature="1" springref="0" springdamper="0 0" damping="1" stiffness="0" solreflimit="0.02 1" solimplimit="0.9 0.95 0.001 0.5 2" solreffriction="0.02 1" solimpfriction="0.9 0.95 0.001 0.5 2" frictionloss="0" limited="true" margin="0" range="30.00002 69.99997" name="ankle_4_68" />
            <geom density="5" type="capsule" size="0.08000002 0.2828431" pos="0.2 -0.2 0" quat="0.7071069 -0.4999999 -0.4999999 0" priority="0" contype="1" conaffinity="0" group="0" condim="3" solmix="1" solref="0.02 1" solimp="0.9 0.95 0.001" margin="0.01" gap="0" friction="1 0.5 0.5" fluidshape="none" fluidcoef="5 0.25 1.5 1 1" name="fourth_ankle_geom_69" />
          </body>
        </body>
      </body>
    </body>
    <geom density="5" type="plane" size="40 40 1" pos="0 0 0" quat="-1 0 0 0" priority="0" contype="1" conaffinity="1" group="0" condim="3" solmix="1" solref="0.02 1" solimp="0.9 0.95 0.001" margin="0.01" gap="0" friction="1 0.5 0.5" fluidshape="none" fluidcoef="5 0.25 1.5 1 1" name="floor_70" />
  </worldbody>
  <contact />
  <tendon />
  <equality />
  <actuator>
    <general joint="hip_4_24" ctrllimited="false" forcelimited="false" ctrlrange="-1 1" forcerange="0 0" lengthrange="0 0" gear="150 0 0 0 0 0" dyntype="none" gaintype="fixed" biastype="none" dynprm="1 0 0" gainprm="1 0 0" biasprm="0 0 0" name="general_4_71" />
    <general joint="hip_4_59" ctrllimited="false" forcelimited="false" ctrlrange="-1 1" forcerange="0 0" lengthrange="0 0" gear="150 0 0 0 0 0" dyntype="none" gaintype="fixed" biastype="none" dynprm="1 0 0" gainprm="1 0 0" biasprm="0 0 0" name="general_4_72" />
    <general joint="ankle_4_33" ctrllimited="false" forcelimited="false" ctrlrange="-1 1" forcerange="0 0" lengthrange="0 0" gear="150 0 0 0 0 0" dyntype="none" gaintype="fixed" biastype="none" dynprm="1 0 0" gainprm="1 0 0" biasprm="0 0 0" name="general_5_73" />
    <general joint="ankle_4_68" ctrllimited="false" forcelimited="false" ctrlrange="-1 1" forcerange="0 0" lengthrange="0 0" gear="150 0 0 0 0 0" dyntype="none" gaintype="fixed" biastype="none" dynprm="1 0 0" gainprm="1 0 0" biasprm="0 0 0" name="general_5_74" />
    <general joint="hip_1_15" ctrllimited="false" forcelimited="false" ctrlrange="-1 1" forcerange="0 0" lengthrange="0 0" gear="150 0 0 0 0 0" dyntype="none" gaintype="fixed" biastype="none" dynprm="1 0 0" gainprm="1 0 0" biasprm="0 0 0" name="general_6_75" />
    <general joint="hip_1_50" ctrllimited="false" forcelimited="false" ctrlrange="-1 1" forcerange="0 0" lengthrange="0 0" gear="150 0 0 0 0 0" dyntype="none" gaintype="fixed" biastype="none" dynprm="1 0 0" gainprm="1 0 0" biasprm="0 0 0" name="general_6_76" />
    <general joint="ankle_1_27" ctrllimited="false" forcelimited="false" ctrlrange="-1 1" forcerange="0 0" lengthrange="0 0" gear="150 0 0 0 0 0" dyntype="none" gaintype="fixed" biastype="none" dynprm="1 0 0" gainprm="1 0 0" biasprm="0 0 0" name="general_7_77" />
    <general joint="ankle_1_62" ctrllimited="false" forcelimited="false" ctrlrange="-1 1" forcerange="0 0" lengthrange="0 0" gear="150 0 0 0 0 0" dyntype="none" gaintype="fixed" biastype="none" dynprm="1 0 0" gainprm="1 0 0" biasprm="0 0 0" name="general_7_78" />
    <general joint="hip_2_18" ctrllimited="false" forcelimited="false" ctrlrange="-1 1" forcerange="0 0" lengthrange="0 0" gear="150 0 0 0 0 0" dyntype="none" gaintype="fixed" biastype="none" dynprm="1 0 0" gainprm="1 0 0" biasprm="0 0 0" name="general_8_79" />
    <general joint="hip_2_53" ctrllimited="false" forcelimited="false" ctrlrange="-1 1" forcerange="0 0" lengthrange="0 0" gear="150 0 0 0 0 0" dyntype="none" gaintype="fixed" biastype="none" dynprm="1 0 0" gainprm="1 0 0" biasprm="0 0 0" name="general_8_80" />
    <general joint="ankle_2_29" ctrllimited="false" forcelimited="false" ctrlrange="-1 1" forcerange="0 0" lengthrange="0 0" gear="150 0 0 0 0 0" dyntype="none" gaintype="fixed" biastype="none" dynprm="1 0 0" gainprm="1 0 0" biasprm="0 0 0" name="general_9_81" />
    <general joint="ankle_2_64" ctrllimited="false" forcelimited="false" ctrlrange="-1 1" forcerange="0 0" lengthrange="0 0" gear="150 0 0 0 0 0" dyntype="none" gaintype="fixed" biastype="none" dynprm="1 0 0" gainprm="1 0 0" biasprm="0 0 0" name="general_9_82" />
    <general joint="hip_3_21" ctrllimited="false" forcelimited="false" ctrlrange="-1 1" forcerange="0 0" lengthrange="0 0" gear="150 0 0 0 0 0" dyntype="none" gaintype="fixed" biastype="none" dynprm="1 0 0" gainprm="1 0 0" biasprm="0 0 0" name="general_10_83" />
    <general joint="hip_3_56" ctrllimited="false" forcelimited="false" ctrlrange="-1 1" forcerange="0 0" lengthrange="0 0" gear="150 0 0 0 0 0" dyntype="none" gaintype="fixed" biastype="none" dynprm="1 0 0" gainprm="1 0 0" biasprm="0 0 0" name="general_10_84" />
    <general joint="ankle_3_31" ctrllimited="false" forcelimited="false" ctrlrange="-1 1" forcerange="0 0" lengthrange="0 0" gear="150 0 0 0 0 0" dyntype="none" gaintype="fixed" biastype="none" dynprm="1 0 0" gainprm="1 0 0" biasprm="0 0 0" name="general_11_85" />
    <general joint="ankle_3_66" ctrllimited="false" forcelimited="false" ctrlrange="-1 1" forcerange="0 0" lengthrange="0 0" gear="150 0 0 0 0 0" dyntype="none" gaintype="fixed" biastype="none" dynprm="1 0 0" gainprm="1 0 0" biasprm="0 0 0" name="general_11_86" />
  </actuator>
  <sensor />
  <compiler coordinate="local" />
  <option gravity="0 0 -9.81" timestep="0.02" />
  <option impratio="1" magnetic="0 0 0" wind="0 0 0" density="0" viscosity="0" o_margin="0" o_solref="0.02 1" o_solimp="0.9 0.95 0.001 0.5 2" integrator="RK4" cone="pyramidal" jacobian="auto" solver="Newton" iterations="100" tolerance="1E-08" noslip_iterations="0" noslip_tolerance="1E-06" mpr_iterations="50" mpr_tolerance="1E-06">
    <flag constraint="enable" equality="enable" frictionloss="enable" limit="enable" contact="enable" passive="enable" gravity="enable" clampctrl="enable" warmstart="enable" filterparent="enable" actuation="enable" refsafe="enable" override="disable" energy="disable" fwdinv="disable" sensornoise="disable" multiccd="disable" />
  </option>
  <size memory="-1" />
  <custom>
    <numeric name="init_qpos" data="0 0 0.55 1 0 0 0 0 1 0 -1 0 -1 0 1" />
  </custom>
  <asset />
</mujoco>