<mujoco>
  <worldbody>
    <geom density="1000" type="plane" size="20 20 1" pos="0 1.88 0" quat="-1 0 0 0" priority="0" contype="0" conaffinity="1" group="0" condim="3" solmix="1" solref="0.02 1" solimp="0.9 0.95 0.001" margin="0" gap="0" friction="1 0.1 0.1" fluidshape="none" fluidcoef="5 0.25 1.5 1 1" name="floor_0" />
    <body pos="0 2.0 1.4" quat="-1 0 0 0" gravcomp="0" name="torso_1">
      <freejoint name="root_2" />
      <geom density="1000" type="capsule" size="0.07 0.07000002" pos="0 0 0" quat="0.7071068 0.7071068 0 0" priority="0" contype="0" conaffinity="0" group="0" condim="3" solmix="1" solref="0.02 1" solimp="0.9 0.95 0.001" margin="0" gap="0" friction="1 0.005 0.0001" fluidshape="none" fluidcoef="5 0.25 1.5 1 1" name="torso1_3" />
      <geom density="1000" type="sphere" size="0.09" pos="0 0 0.1899999" quat="-1 0 0 0" priority="0" contype="0" conaffinity="0" group="0" condim="3" solmix="1" solref="0.02 1" solimp="0.9 0.95 0.001" margin="0" gap="0" friction="1 0.005 0.0001" fluidshape="none" fluidcoef="5 0.25 1.5 1 1" name="head_4" />
      <geom density="1000" type="capsule" size="0.06 0.06000001" pos="-0.01 0 -0.12" quat="0.7071068 0.7071068 0 0" priority="0" contype="0" conaffinity="0" group="0" condim="3" solmix="1" solref="0.02 1" solimp="0.9 0.95 0.001" margin="0" gap="0" friction="1 0.005 0.0001" fluidshape="none" fluidcoef="5 0.25 1.5 1 1" name="uwaist_5" />
      <body pos="-0.01 0 -0.26" quat="0.999998 0 -0.002 0" gravcomp="0" name="lwaist_6">
        <joint type="hinge" pos="2.669552E-10 0 0.06499998" axis="-4.76837E-07 0 1" ref="0" armature="0.02" springref="0" springdamper="0 0" damping="5" stiffness="20" solreflimit="0.02 1" solimplimit="0.9 0.95 0.001 0.5 2" solreffriction="0.02 1" solimpfriction="0.9 0.95 0.001 0.5 2" frictionloss="0" limited="true" margin="0" range="-44.99999 44.99999" name="abdomen_z_9" />
        <joint type="hinge" pos="2.669552E-10 0 0.06499998" axis="-3.576278E-07 1 0" ref="0" armature="0.02" springref="0" springdamper="0 0" damping="5" stiffness="10" solreflimit="0.02 1" solimplimit="0.9 0.95 0.001 0.5 2" solreffriction="0.02 1" solimpfriction="0.9 0.95 0.001 0.5 2" frictionloss="0" limited="true" margin="0" range="-75.00018 30.00002" name="abdomen_y_10" />
        <geom density="1000" type="capsule" size="0.06 0.06000002" pos="0 0 0" quat="0.7071069 0.7071069 1.74352E-11 -1.74352E-11" priority="0" contype="0" conaffinity="0" group="0" condim="3" solmix="1" solref="0.02 1" solimp="0.9 0.95 0.001" margin="0" gap="0" friction="1 0.005 0.0001" fluidshape="none" fluidcoef="5 0.25 1.5 1 1" name="lwaist_11" />
        <body pos="-1.778979E-10 0 -0.165" quat="0.9999981 0 -0.002 0" gravcomp="0" name="pelvis_12">
          <joint type="hinge" pos="1.34564E-10 0 0.1" axis="1 0 0" ref="0" armature="0.02" springref="0" springdamper="0 0" damping="5" stiffness="10" solreflimit="0.02 1" solimplimit="0.9 0.95 0.001 0.5 2" solreffriction="0.02 1" solimpfriction="0.9 0.95 0.001 0.5 2" frictionloss="0" limited="true" margin="0" range="-34.99998 34.99998" name="abdomen_x_21" />
          <geom density="1000" type="capsule" size="0.09 0.07000005" pos="-0.02 0 -4.003656E-08" quat="0.707107 0.707107 1.94617E-10 -1.94617E-10" priority="0" contype="0" conaffinity="0" group="0" condim="3" solmix="1" solref="0.02 1" solimp="0.9 0.95 0.001" margin="0" gap="0" friction="1 0.005 0.0001" fluidshape="none" fluidcoef="5 0.25 1.5 1 1" name="butt_22" />
          <body pos="-4.352916E-10 -0.1 -0.04000005" quat="-1 0 0 0" gravcomp="0" name="right_thigh_23">
            <joint type="hinge" pos="0 0 0" axis="1 0 0" ref="0" armature="0.01" springref="0" springdamper="0 0" damping="5" stiffness="10" solreflimit="0.02 1" solimplimit="0.9 0.95 0.001 0.5 2" solreffriction="0.02 1" solimpfriction="0.9 0.95 0.001 0.5 2" frictionloss="0" limited="true" margin="0" range="-24.99998 5.000002" name="right_hip_x_31" />
            <joint type="hinge" pos="0 0 0" axis="-5.960461E-07 0 1" ref="0" armature="0.01" springref="0" springdamper="0 0" damping="5" stiffness="10" solreflimit="0.02 1" solimplimit="0.9 0.95 0.001 0.5 2" solreffriction="0.02 1" solimpfriction="0.9 0.95 0.001 0.5 2" frictionloss="0" limited="true" margin="0" range="-60.00014 34.99998" name="right_hip_z_32" />
            <joint type="hinge" pos="0 0 0" axis="-5.960461E-07 1 0" ref="0" armature="0.008" springref="0" springdamper="0 0" damping="5" stiffness="20" solreflimit="0.02 1" solimplimit="0.9 0.95 0.001 0.5 2" solreffriction="0.02 1" solimpfriction="0.9 0.95 0.001 0.5 2" frictionloss="0" limited="true" margin="0" range="-109.9999 20.00001" name="right_hip_y_33" />
            <geom density="1000" type="capsule" size="0.06 0.170074" pos="5.229871E-10 0.004999995 -0.17" quat="0.9998921 0.0147011 1.165678E-10 -9.564907E-13" priority="0" contype="0" conaffinity="0" group="0" condim="3" solmix="1" solref="0.02 1" solimp="0.9 0.95 0.001" margin="0" gap="0" friction="1 0.005 0.0001" fluidshape="none" fluidcoef="5 0.25 1.5 1 1" name="right_thigh1_34" />
            <body pos="3.726947E-10 0.00999999 -0.403" quat="-1 0 0 0" gravcomp="0" name="right_shin_35">
              <joint type="hinge" pos="2.176458E-10 0 0.02000003" axis="-5.960461E-07 -1 0" ref="0" armature="0.006" springref="0" springdamper="0 0" damping="1" stiffness="0" solreflimit="0.02 1" solimplimit="0.9 0.95 0.001 0.5 2" solreffriction="0.02 1" solimpfriction="0.9 0.95 0.001 0.5 2" frictionloss="0" limited="true" margin="0" range="-160.0002 -2.000001" name="right_knee_41" />
              <geom density="1000" type="capsule" size="0.049 0.15" pos="2.749865E-10 0 -0.1499999" quat="-1 0 0 0" priority="0" contype="0" conaffinity="0" group="0" condim="3" solmix="1" solref="0.02 1" solimp="0.9 0.95 0.001" margin="0" gap="0" friction="1 0.005 0.0001" fluidshape="none" fluidcoef="5 0.25 1.5 1 1" name="right_shin1_42" />
              <body pos="-1.287055E-10 0 -0.45" quat="-1 0 0 0" gravcomp="0" name="right_foot_43">
                <geom density="1000" type="sphere" size="0.075" pos="-3.534547E-10 0 0.09999988" quat="-1 0 0 0" priority="0" contype="1" conaffinity="0" group="0" condim="3" solmix="1" solref="0.02 1" solimp="0.9 0.95 0.001" margin="0" gap="0" friction="1 0.005 0.0001" fluidshape="none" fluidcoef="5 0.25 1.5 1 1" name="right_foot_47" />
              </body>
            </body>
          </body>
          <body pos="-4.352916E-10 0.1 -0.04000005" quat="-1 0 0 0" gravcomp="0" name="left_thigh_24">
            <joint type="hinge" pos="0 0 0" axis="-1 0 0" ref="0" armature="0.01" springref="0" springdamper="0 0" damping="5" stiffness="10" solreflimit="0.02 1" solimplimit="0.9 0.95 0.001 0.5 2" solreffriction="0.02 1" solimpfriction="0.9 0.95 0.001 0.5 2" frictionloss="0" limited="true" margin="0" range="-24.99998 5.000002" name="left_hip_x_36" />
            <joint type="hinge" pos="0 0 0" axis="-4.768369E-07 0 -1" ref="0" armature="0.01" springref="0" springdamper="0 0" damping="5" stiffness="10" solreflimit="0.02 1" solimplimit="0.9 0.95 0.001 0.5 2" solreffriction="0.02 1" solimpfriction="0.9 0.95 0.001 0.5 2" frictionloss="0" limited="true" margin="0" range="-60.00014 34.99998" name="left_hip_z_37" />
            <joint type="hinge" pos="0 0 0" axis="-5.960461E-07 1 0" ref="0" armature="0.01" springref="0" springdamper="0 0" damping="5" stiffness="20" solreflimit="0.02 1" solimplimit="0.9 0.95 0.001 0.5 2" solreffriction="0.02 1" solimpfriction="0.9 0.95 0.001 0.5 2" frictionloss="0" limited="true" margin="0" range="-109.9999 20.00001" name="left_hip_y_38" />
            <geom density="1000" type="capsule" size="0.06 0.170074" pos="5.229871E-10 -0.004999995 -0.17" quat="0.9998921 -0.0147011 1.165678E-10 9.564907E-13" priority="0" contype="0" conaffinity="0" group="0" condim="3" solmix="1" solref="0.02 1" solimp="0.9 0.95 0.001" margin="0" gap="0" friction="1 0.005 0.0001" fluidshape="none" fluidcoef="5 0.25 1.5 1 1" name="left_thigh1_39" />
            <body pos="3.726947E-10 -0.00999999 -0.403" quat="-1 0 0 0" gravcomp="0" name="left_shin_40">
              <joint type="hinge" pos="2.176458E-10 0 0.02000003" axis="-5.960461E-07 -1 0" ref="0" armature="0.006" springref="0" springdamper="0 0" damping="1" stiffness="1" solreflimit="0.02 1" solimplimit="0.9 0.95 0.001 0.5 2" solreffriction="0.02 1" solimpfriction="0.9 0.95 0.001 0.5 2" frictionloss="0" limited="true" margin="0" range="-160.0002 -2.000001" name="left_knee_44" />
              <geom density="1000" type="capsule" size="0.049 0.15" pos="2.749865E-10 0 -0.1499999" quat="-1 0 0 0" priority="0" contype="0" conaffinity="0" group="0" condim="3" solmix="1" solref="0.02 1" solimp="0.9 0.95 0.001" margin="0" gap="0" friction="1 0.005 0.0001" fluidshape="none" fluidcoef="5 0.25 1.5 1 1" name="left_shin1_45" />
              <body pos="-1.287055E-10 0 -0.45" quat="-1 0 0 0" gravcomp="0" name="left_foot_46">
                <geom density="1000" type="sphere" size="0.075" pos="-3.534547E-10 0 0.09999988" quat="-1 0 0 0" priority="0" contype="1" conaffinity="0" group="0" condim="3" solmix="1" solref="0.02 1" solimp="0.9 0.95 0.001" margin="0" gap="0" friction="1 0.005 0.0001" fluidshape="none" fluidcoef="5 0.25 1.5 1 1" name="left_foot_48" />
              </body>
            </body>
          </body>
        </body>
      </body>
      <body pos="0 -0.17 0.05999994" quat="-1 0 0 0" gravcomp="0" name="right_upper_arm_7">
        <joint type="hinge" pos="0 0 0" axis="0.8164969 0.408248 0.408248" ref="0" armature="0.0068" springref="0" springdamper="0 0" damping="1" stiffness="1" solreflimit="0.02 1" solimplimit="0.9 0.95 0.001 0.5 2" solreffriction="0.02 1" solimpfriction="0.9 0.95 0.001 0.5 2" frictionloss="0" limited="true" margin="0" range="-85.00001 60.00014" name="right_shoulder1_13" />
        <joint type="hinge" pos="0 0 0" axis="0 -0.7071068 0.7071068" ref="0" armature="0.0051" springref="0" springdamper="0 0" damping="1" stiffness="1" solreflimit="0.02 1" solimplimit="0.9 0.95 0.001 0.5 2" solreffriction="0.02 1" solimpfriction="0.9 0.95 0.001 0.5 2" frictionloss="0" limited="true" margin="0" range="-85.00001 60.00014" name="right_shoulder2_14" />
        <geom density="1000" type="capsule" size="0.04 0.138564" pos="0.08 -0.08000004 -0.07999992" quat="0.8880737 -0.3250579 -0.3250579 0" priority="0" contype="0" conaffinity="0" group="0" condim="3" solmix="1" solref="0.02 1" solimp="0.9 0.95 0.001" margin="0" gap="0" friction="1 0.005 0.0001" fluidshape="none" fluidcoef="5 0.25 1.5 1 1" name="right_uarm1_15" />
        <body pos="0.18 -0.1800001 -0.1799999" quat="-1 0 0 0" gravcomp="0" name="right_lower_arm_16">
          <joint type="hinge" pos="0 0 0" axis="0 -0.7071068 0.7071068" ref="0" armature="0.0028" springref="0" springdamper="0 0" damping="1" stiffness="0" solreflimit="0.02 1" solimplimit="0.9 0.95 0.001 0.5 2" solreffriction="0.02 1" solimpfriction="0.9 0.95 0.001 0.5 2" frictionloss="0" limited="true" margin="0" range="-90.00021 50.00002" name="right_elbow_25" />
          <geom density="1000" type="capsule" size="0.031 0.138564" pos="0.09 0.09000003 0.09000003" quat="0.459701 0.627963 -0.627963 0" priority="0" contype="0" conaffinity="0" group="0" condim="3" solmix="1" solref="0.02 1" solimp="0.9 0.95 0.001" margin="0" gap="0" friction="1 0.005 0.0001" fluidshape="none" fluidcoef="5 0.25 1.5 1 1" name="right_larm_26" />
          <geom density="1000" type="sphere" size="0.04" pos="0.18 0.1800001 0.1799999" quat="-1 0 0 0" priority="0" contype="0" conaffinity="0" group="0" condim="3" solmix="1" solref="0.02 1" solimp="0.9 0.95 0.001" margin="0" gap="0" friction="1 0.005 0.0001" fluidshape="none" fluidcoef="5 0.25 1.5 1 1" name="right_hand_27" />
        </body>
      </body>
      <body pos="0 0.17 0.05999994" quat="-1 0 0 0" gravcomp="0" name="left_upper_arm_8">
        <joint type="hinge" pos="0 0 0" axis="0.8164969 -0.408248 0.408248" ref="0" armature="0.0068" springref="0" springdamper="0 0" damping="1" stiffness="1" solreflimit="0.02 1" solimplimit="0.9 0.95 0.001 0.5 2" solreffriction="0.02 1" solimpfriction="0.9 0.95 0.001 0.5 2" frictionloss="0" limited="true" margin="0" range="-60.00014 85.00001" name="left_shoulder1_17" />
        <joint type="hinge" pos="0 0 0" axis="0 0.7071068 0.7071068" ref="0" armature="0.0051" springref="0" springdamper="0 0" damping="1" stiffness="1" solreflimit="0.02 1" solimplimit="0.9 0.95 0.001 0.5 2" solreffriction="0.02 1" solimpfriction="0.9 0.95 0.001 0.5 2" frictionloss="0" limited="true" margin="0" range="-60.00014 85.00001" name="left_shoulder2_18" />
        <geom density="1000" type="capsule" size="0.04 0.138564" pos="0.08 0.08000016 -0.07999992" quat="0.8880737 0.3250579 -0.3250579 0" priority="0" contype="0" conaffinity="0" group="0" condim="3" solmix="1" solref="0.02 1" solimp="0.9 0.95 0.001" margin="0" gap="0" friction="1 0.005 0.0001" fluidshape="none" fluidcoef="5 0.25 1.5 1 1" name="left_uarm1_19" />
        <body pos="0.18 0.1800001 -0.1799999" quat="-1 0 0 0" gravcomp="0" name="left_lower_arm_20">
          <joint type="hinge" pos="0 0 0" axis="0 -0.7071068 -0.7071068" ref="0" armature="0.0028" springref="0" springdamper="0 0" damping="1" stiffness="0" solreflimit="0.02 1" solimplimit="0.9 0.95 0.001 0.5 2" solreffriction="0.02 1" solimpfriction="0.9 0.95 0.001 0.5 2" frictionloss="0" limited="true" margin="0" range="-90.00021 50.00002" name="left_elbow_28" />
          <geom density="1000" type="capsule" size="0.031 0.138564" pos="0.09 -0.09000015 0.09000003" quat="0.459701 -0.627963 -0.627963 0" priority="0" contype="0" conaffinity="0" group="0" condim="3" solmix="1" solref="0.02 1" solimp="0.9 0.95 0.001" margin="0" gap="0" friction="1 0.005 0.0001" fluidshape="none" fluidcoef="5 0.25 1.5 1 1" name="left_larm_29" />
          <geom density="1000" type="sphere" size="0.04" pos="0.18 -0.1800001 0.1799999" quat="-1 0 0 0" priority="0" contype="0" conaffinity="0" group="0" condim="3" solmix="1" solref="0.02 1" solimp="0.9 0.95 0.001" margin="0" gap="0" friction="1 0.005 0.0001" fluidshape="none" fluidcoef="5 0.25 1.5 1 1" name="left_hand_30" />
        </body>
      </body>
    </body>
    <body pos="0 0 1.4" quat="-1 0 0 0" gravcomp="0" name="torso_49">
      <freejoint name="root_50" />
      <geom density="1000" type="capsule" size="0.07 0.07000002" pos="0 0 0" quat="0.7071068 0.7071068 0 0" priority="0" contype="0" conaffinity="0" group="0" condim="3" solmix="1" solref="0.02 1" solimp="0.9 0.95 0.001" margin="0" gap="0" friction="1 0.005 0.0001" fluidshape="none" fluidcoef="5 0.25 1.5 1 1" name="torso1_51" />
      <geom density="1000" type="sphere" size="0.09" pos="0 0 0.1899999" quat="-1 0 0 0" priority="0" contype="0" conaffinity="0" group="0" condim="3" solmix="1" solref="0.02 1" solimp="0.9 0.95 0.001" margin="0" gap="0" friction="1 0.005 0.0001" fluidshape="none" fluidcoef="5 0.25 1.5 1 1" name="head_52" />
      <geom density="1000" type="capsule" size="0.06 0.06000001" pos="-0.01 0 -0.12" quat="0.7071068 0.7071068 0 0" priority="0" contype="0" conaffinity="0" group="0" condim="3" solmix="1" solref="0.02 1" solimp="0.9 0.95 0.001" margin="0" gap="0" friction="1 0.005 0.0001" fluidshape="none" fluidcoef="5 0.25 1.5 1 1" name="uwaist_53" />
      <body pos="-0.01 0 -0.26" quat="0.999998 0 -0.002 0" gravcomp="0" name="lwaist_54">
        <joint type="hinge" pos="2.669552E-10 0 0.06499998" axis="-4.76837E-07 0 1" ref="0" armature="0.02" springref="0" springdamper="0 0" damping="5" stiffness="20" solreflimit="0.02 1" solimplimit="0.9 0.95 0.001 0.5 2" solreffriction="0.02 1" solimpfriction="0.9 0.95 0.001 0.5 2" frictionloss="0" limited="true" margin="0" range="-44.99999 44.99999" name="abdomen_z_57" />
        <joint type="hinge" pos="2.669552E-10 0 0.06499998" axis="-3.576278E-07 1 0" ref="0" armature="0.02" springref="0" springdamper="0 0" damping="5" stiffness="10" solreflimit="0.02 1" solimplimit="0.9 0.95 0.001 0.5 2" solreffriction="0.02 1" solimpfriction="0.9 0.95 0.001 0.5 2" frictionloss="0" limited="true" margin="0" range="-75.00018 30.00002" name="abdomen_y_58" />
        <geom density="1000" type="capsule" size="0.06 0.06000002" pos="0 0 0" quat="0.7071069 0.7071069 1.74352E-11 -1.74352E-11" priority="0" contype="0" conaffinity="0" group="0" condim="3" solmix="1" solref="0.02 1" solimp="0.9 0.95 0.001" margin="0" gap="0" friction="1 0.005 0.0001" fluidshape="none" fluidcoef="5 0.25 1.5 1 1" name="lwaist_59" />
        <body pos="-1.778979E-10 0 -0.165" quat="0.9999981 0 -0.002 0" gravcomp="0" name="pelvis_60">
          <joint type="hinge" pos="1.34564E-10 0 0.1" axis="1 0 0" ref="0" armature="0.02" springref="0" springdamper="0 0" damping="5" stiffness="10" solreflimit="0.02 1" solimplimit="0.9 0.95 0.001 0.5 2" solreffriction="0.02 1" solimpfriction="0.9 0.95 0.001 0.5 2" frictionloss="0" limited="true" margin="0" range="-34.99998 34.99998" name="abdomen_x_69" />
          <geom density="1000" type="capsule" size="0.09 0.07000005" pos="-0.02 0 -4.003656E-08" quat="0.707107 0.707107 1.94617E-10 -1.94617E-10" priority="0" contype="0" conaffinity="0" group="0" condim="3" solmix="1" solref="0.02 1" solimp="0.9 0.95 0.001" margin="0" gap="0" friction="1 0.005 0.0001" fluidshape="none" fluidcoef="5 0.25 1.5 1 1" name="butt_70" />
          <body pos="-4.352916E-10 -0.1 -0.04000005" quat="-1 0 0 0" gravcomp="0" name="right_thigh_71">
            <joint type="hinge" pos="0 0 0" axis="1 0 0" ref="0" armature="0.01" springref="0" springdamper="0 0" damping="5" stiffness="10" solreflimit="0.02 1" solimplimit="0.9 0.95 0.001 0.5 2" solreffriction="0.02 1" solimpfriction="0.9 0.95 0.001 0.5 2" frictionloss="0" limited="true" margin="0" range="-24.99998 5.000002" name="right_hip_x_79" />
            <joint type="hinge" pos="0 0 0" axis="-5.960461E-07 0 1" ref="0" armature="0.01" springref="0" springdamper="0 0" damping="5" stiffness="10" solreflimit="0.02 1" solimplimit="0.9 0.95 0.001 0.5 2" solreffriction="0.02 1" solimpfriction="0.9 0.95 0.001 0.5 2" frictionloss="0" limited="true" margin="0" range="-60.00014 34.99998" name="right_hip_z_80" />
            <joint type="hinge" pos="0 0 0" axis="-5.960461E-07 1 0" ref="0" armature="0.008" springref="0" springdamper="0 0" damping="5" stiffness="20" solreflimit="0.02 1" solimplimit="0.9 0.95 0.001 0.5 2" solreffriction="0.02 1" solimpfriction="0.9 0.95 0.001 0.5 2" frictionloss="0" limited="true" margin="0" range="-109.9999 20.00001" name="right_hip_y_81" />
            <geom density="1000" type="capsule" size="0.06 0.170074" pos="5.229871E-10 0.005000003 -0.17" quat="0.9998921 0.0147011 1.165678E-10 -9.564907E-13" priority="0" contype="0" conaffinity="0" group="0" condim="3" solmix="1" solref="0.02 1" solimp="0.9 0.95 0.001" margin="0" gap="0" friction="1 0.005 0.0001" fluidshape="none" fluidcoef="5 0.25 1.5 1 1" name="right_thigh1_82" />
            <body pos="3.726947E-10 0.009999998 -0.403" quat="-1 0 0 0" gravcomp="0" name="right_shin_83">
              <joint type="hinge" pos="2.176458E-10 0 0.02000003" axis="-5.960461E-07 -1 0" ref="0" armature="0.006" springref="0" springdamper="0 0" damping="1" stiffness="0" solreflimit="0.02 1" solimplimit="0.9 0.95 0.001 0.5 2" solreffriction="0.02 1" solimpfriction="0.9 0.95 0.001 0.5 2" frictionloss="0" limited="true" margin="0" range="-160.0002 -2.000001" name="right_knee_89" />
              <geom density="1000" type="capsule" size="0.049 0.15" pos="2.749865E-10 0 -0.1499999" quat="-1 0 0 0" priority="0" contype="0" conaffinity="0" group="0" condim="3" solmix="1" solref="0.02 1" solimp="0.9 0.95 0.001" margin="0" gap="0" friction="1 0.005 0.0001" fluidshape="none" fluidcoef="5 0.25 1.5 1 1" name="right_shin1_90" />
              <body pos="-1.287055E-10 0 -0.45" quat="-1 0 0 0" gravcomp="0" name="right_foot_91">
                <geom density="1000" type="sphere" size="0.075" pos="-3.534547E-10 0 0.09999988" quat="-1 0 0 0" priority="0" contype="1" conaffinity="0" group="0" condim="3" solmix="1" solref="0.02 1" solimp="0.9 0.95 0.001" margin="0" gap="0" friction="1 0.005 0.0001" fluidshape="none" fluidcoef="5 0.25 1.5 1 1" name="right_foot_95" />
              </body>
            </body>
          </body>
          <body pos="-4.352916E-10 0.1 -0.04000005" quat="-1 0 0 0" gravcomp="0" name="left_thigh_72">
            <joint type="hinge" pos="0 0 0" axis="-1 0 0" ref="0" armature="0.01" springref="0" springdamper="0 0" damping="5" stiffness="10" solreflimit="0.02 1" solimplimit="0.9 0.95 0.001 0.5 2" solreffriction="0.02 1" solimpfriction="0.9 0.95 0.001 0.5 2" frictionloss="0" limited="true" margin="0" range="-24.99998 5.000002" name="left_hip_x_84" />
            <joint type="hinge" pos="0 0 0" axis="-4.768369E-07 0 -1" ref="0" armature="0.01" springref="0" springdamper="0 0" damping="5" stiffness="10" solreflimit="0.02 1" solimplimit="0.9 0.95 0.001 0.5 2" solreffriction="0.02 1" solimpfriction="0.9 0.95 0.001 0.5 2" frictionloss="0" limited="true" margin="0" range="-60.00014 34.99998" name="left_hip_z_85" />
            <joint type="hinge" pos="0 0 0" axis="-5.960461E-07 1 0" ref="0" armature="0.01" springref="0" springdamper="0 0" damping="5" stiffness="20" solreflimit="0.02 1" solimplimit="0.9 0.95 0.001 0.5 2" solreffriction="0.02 1" solimpfriction="0.9 0.95 0.001 0.5 2" frictionloss="0" limited="true" margin="0" range="-109.9999 20.00001" name="left_hip_y_86" />
            <geom density="1000" type="capsule" size="0.06 0.170074" pos="5.229871E-10 -0.005000003 -0.17" quat="0.9998921 -0.0147011 1.165678E-10 9.564907E-13" priority="0" contype="0" conaffinity="0" group="0" condim="3" solmix="1" solref="0.02 1" solimp="0.9 0.95 0.001" margin="0" gap="0" friction="1 0.005 0.0001" fluidshape="none" fluidcoef="5 0.25 1.5 1 1" name="left_thigh1_87" />
            <body pos="3.726947E-10 -0.009999998 -0.403" quat="-1 0 0 0" gravcomp="0" name="left_shin_88">
              <joint type="hinge" pos="2.176458E-10 0 0.02000003" axis="-5.960461E-07 -1 0" ref="0" armature="0.006" springref="0" springdamper="0 0" damping="1" stiffness="1" solreflimit="0.02 1" solimplimit="0.9 0.95 0.001 0.5 2" solreffriction="0.02 1" solimpfriction="0.9 0.95 0.001 0.5 2" frictionloss="0" limited="true" margin="0" range="-160.0002 -2.000001" name="left_knee_92" />
              <geom density="1000" type="capsule" size="0.049 0.15" pos="2.749865E-10 0 -0.1499999" quat="-1 0 0 0" priority="0" contype="0" conaffinity="0" group="0" condim="3" solmix="1" solref="0.02 1" solimp="0.9 0.95 0.001" margin="0" gap="0" friction="1 0.005 0.0001" fluidshape="none" fluidcoef="5 0.25 1.5 1 1" name="left_shin1_93" />
              <body pos="-1.287055E-10 0 -0.45" quat="-1 0 0 0" gravcomp="0" name="left_foot_94">
                <geom density="1000" type="sphere" size="0.075" pos="-3.534547E-10 0 0.09999988" quat="-1 0 0 0" priority="0" contype="1" conaffinity="0" group="0" condim="3" solmix="1" solref="0.02 1" solimp="0.9 0.95 0.001" margin="0" gap="0" friction="1 0.005 0.0001" fluidshape="none" fluidcoef="5 0.25 1.5 1 1" name="left_foot_96" />
              </body>
            </body>
          </body>
        </body>
      </body>
      <body pos="0 -0.17 0.05999994" quat="-1 0 0 0" gravcomp="0" name="right_upper_arm_55">
        <joint type="hinge" pos="0 0 0" axis="0.8164969 0.408248 0.408248" ref="0" armature="0.0068" springref="0" springdamper="0 0" damping="1" stiffness="1" solreflimit="0.02 1" solimplimit="0.9 0.95 0.001 0.5 2" solreffriction="0.02 1" solimpfriction="0.9 0.95 0.001 0.5 2" frictionloss="0" limited="true" margin="0" range="-85.00001 60.00014" name="right_shoulder1_61" />
        <joint type="hinge" pos="0 0 0" axis="0 -0.7071068 0.7071068" ref="0" armature="0.0051" springref="0" springdamper="0 0" damping="1" stiffness="1" solreflimit="0.02 1" solimplimit="0.9 0.95 0.001 0.5 2" solreffriction="0.02 1" solimpfriction="0.9 0.95 0.001 0.5 2" frictionloss="0" limited="true" margin="0" range="-85.00001 60.00014" name="right_shoulder2_62" />
        <geom density="1000" type="capsule" size="0.04 0.138564" pos="0.08 -0.08 -0.07999992" quat="0.8880737 -0.3250579 -0.3250579 0" priority="0" contype="0" conaffinity="0" group="0" condim="3" solmix="1" solref="0.02 1" solimp="0.9 0.95 0.001" margin="0" gap="0" friction="1 0.005 0.0001" fluidshape="none" fluidcoef="5 0.25 1.5 1 1" name="right_uarm1_63" />
        <body pos="0.18 -0.18 -0.1799999" quat="-1 0 0 0" gravcomp="0" name="right_lower_arm_64">
          <joint type="hinge" pos="0 0 0" axis="0 -0.7071068 0.7071068" ref="0" armature="0.0028" springref="0" springdamper="0 0" damping="1" stiffness="0" solreflimit="0.02 1" solimplimit="0.9 0.95 0.001 0.5 2" solreffriction="0.02 1" solimpfriction="0.9 0.95 0.001 0.5 2" frictionloss="0" limited="true" margin="0" range="-90.00021 50.00002" name="right_elbow_73" />
          <geom density="1000" type="capsule" size="0.031 0.138564" pos="0.09 0.09000003 0.09000003" quat="0.459701 0.627963 -0.627963 0" priority="0" contype="0" conaffinity="0" group="0" condim="3" solmix="1" solref="0.02 1" solimp="0.9 0.95 0.001" margin="0" gap="0" friction="1 0.005 0.0001" fluidshape="none" fluidcoef="5 0.25 1.5 1 1" name="right_larm_74" />
          <geom density="1000" type="sphere" size="0.04" pos="0.18 0.18 0.1799999" quat="-1 0 0 0" priority="0" contype="0" conaffinity="0" group="0" condim="3" solmix="1" solref="0.02 1" solimp="0.9 0.95 0.001" margin="0" gap="0" friction="1 0.005 0.0001" fluidshape="none" fluidcoef="5 0.25 1.5 1 1" name="right_hand_75" />
        </body>
      </body>
      <body pos="0 0.17 0.05999994" quat="-1 0 0 0" gravcomp="0" name="left_upper_arm_56">
        <joint type="hinge" pos="0 0 0" axis="0.8164969 -0.408248 0.408248" ref="0" armature="0.0068" springref="0" springdamper="0 0" damping="1" stiffness="1" solreflimit="0.02 1" solimplimit="0.9 0.95 0.001 0.5 2" solreffriction="0.02 1" solimpfriction="0.9 0.95 0.001 0.5 2" frictionloss="0" limited="true" margin="0" range="-60.00014 85.00001" name="left_shoulder1_65" />
        <joint type="hinge" pos="0 0 0" axis="0 0.7071068 0.7071068" ref="0" armature="0.0051" springref="0" springdamper="0 0" damping="1" stiffness="1" solreflimit="0.02 1" solimplimit="0.9 0.95 0.001 0.5 2" solreffriction="0.02 1" solimpfriction="0.9 0.95 0.001 0.5 2" frictionloss="0" limited="true" margin="0" range="-60.00014 85.00001" name="left_shoulder2_66" />
        <geom density="1000" type="capsule" size="0.04 0.138564" pos="0.08 0.08 -0.07999992" quat="0.8880737 0.3250579 -0.3250579 0" priority="0" contype="0" conaffinity="0" group="0" condim="3" solmix="1" solref="0.02 1" solimp="0.9 0.95 0.001" margin="0" gap="0" friction="1 0.005 0.0001" fluidshape="none" fluidcoef="5 0.25 1.5 1 1" name="left_uarm1_67" />
        <body pos="0.18 0.18 -0.1799999" quat="-1 0 0 0" gravcomp="0" name="left_lower_arm_68">
          <joint type="hinge" pos="0 0 0" axis="0 -0.7071068 -0.7071068" ref="0" armature="0.0028" springref="0" springdamper="0 0" damping="1" stiffness="0" solreflimit="0.02 1" solimplimit="0.9 0.95 0.001 0.5 2" solreffriction="0.02 1" solimpfriction="0.9 0.95 0.001 0.5 2" frictionloss="0" limited="true" margin="0" range="-90.00021 50.00002" name="left_elbow_76" />
          <geom density="1000" type="capsule" size="0.031 0.138564" pos="0.09 -0.09000003 0.09000003" quat="0.459701 -0.627963 -0.627963 0" priority="0" contype="0" conaffinity="0" group="0" condim="3" solmix="1" solref="0.02 1" solimp="0.9 0.95 0.001" margin="0" gap="0" friction="1 0.005 0.0001" fluidshape="none" fluidcoef="5 0.25 1.5 1 1" name="left_larm_77" />
          <geom density="1000" type="sphere" size="0.04" pos="0.18 -0.18 0.1799999" quat="-1 0 0 0" priority="0" contype="0" conaffinity="0" group="0" condim="3" solmix="1" solref="0.02 1" solimp="0.9 0.95 0.001" margin="0" gap="0" friction="1 0.005 0.0001" fluidshape="none" fluidcoef="5 0.25 1.5 1 1" name="left_hand_78" />
        </body>
      </body>
    </body>
    <geom density="1000" type="plane" size="20 20 1" pos="0 0 0" quat="-1 0 0 0" priority="0" contype="0" conaffinity="1" group="0" condim="3" solmix="1" solref="0.02 1" solimp="0.9 0.95 0.001" margin="0" gap="0" friction="1 0.1 0.1" fluidshape="none" fluidcoef="5 0.25 1.5 1 1" name="floor_97" />
  </worldbody>
  <contact />
  <tendon />
  <equality />
  <actuator>
    <general joint="abdomen_y_10" ctrllimited="true" forcelimited="false" ctrlrange="-0.4 0.4" forcerange="0 0" lengthrange="0 0" gear="100 0 0 0 0 0" dyntype="none" gaintype="fixed" biastype="none" dynprm="1 0 0" gainprm="1 0 0" biasprm="0 0 0" name="abdomen_y_98" />
    <general joint="abdomen_y_58" ctrllimited="true" forcelimited="false" ctrlrange="-0.4 0.4" forcerange="0 0" lengthrange="0 0" gear="100 0 0 0 0 0" dyntype="none" gaintype="fixed" biastype="none" dynprm="1 0 0" gainprm="1 0 0" biasprm="0 0 0" name="abdomen_y_99" />
    <general joint="abdomen_z_9" ctrllimited="true" forcelimited="false" ctrlrange="-0.4 0.4" forcerange="0 0" lengthrange="0 0" gear="100 0 0 0 0 0" dyntype="none" gaintype="fixed" biastype="none" dynprm="1 0 0" gainprm="1 0 0" biasprm="0 0 0" name="abdomen_z_100" />
    <general joint="abdomen_z_57" ctrllimited="true" forcelimited="false" ctrlrange="-0.4 0.4" forcerange="0 0" lengthrange="0 0" gear="100 0 0 0 0 0" dyntype="none" gaintype="fixed" biastype="none" dynprm="1 0 0" gainprm="1 0 0" biasprm="0 0 0" name="abdomen_z_101" />
    <general joint="abdomen_x_21" ctrllimited="true" forcelimited="false" ctrlrange="-0.4 0.4" forcerange="0 0" lengthrange="0 0" gear="100 0 0 0 0 0" dyntype="none" gaintype="fixed" biastype="none" dynprm="1 0 0" gainprm="1 0 0" biasprm="0 0 0" name="abdomen_x_102" />
    <general joint="abdomen_x_69" ctrllimited="true" forcelimited="false" ctrlrange="-0.4 0.4" forcerange="0 0" lengthrange="0 0" gear="100 0 0 0 0 0" dyntype="none" gaintype="fixed" biastype="none" dynprm="1 0 0" gainprm="1 0 0" biasprm="0 0 0" name="abdomen_x_103" />
    <general joint="right_hip_x_31" ctrllimited="true" forcelimited="false" ctrlrange="-0.4 0.4" forcerange="0 0" lengthrange="0 0" gear="100 0 0 0 0 0" dyntype="none" gaintype="fixed" biastype="none" dynprm="1 0 0" gainprm="1 0 0" biasprm="0 0 0" name="right_hip_x_104" />
    <general joint="right_hip_x_79" ctrllimited="true" forcelimited="false" ctrlrange="-0.4 0.4" forcerange="0 0" lengthrange="0 0" gear="100 0 0 0 0 0" dyntype="none" gaintype="fixed" biastype="none" dynprm="1 0 0" gainprm="1 0 0" biasprm="0 0 0" name="right_hip_x_105" />
    <general joint="right_hip_z_32" ctrllimited="true" forcelimited="false" ctrlrange="-0.4 0.4" forcerange="0 0" lengthrange="0 0" gear="100 0 0 0 0 0" dyntype="none" gaintype="fixed" biastype="none" dynprm="1 0 0" gainprm="1 0 0" biasprm="0 0 0" name="right_hip_z_106" />
    <general joint="right_hip_z_80" ctrllimited="true" forcelimited="false" ctrlrange="-0.4 0.4" forcerange="0 0" lengthrange="0 0" gear="100 0 0 0 0 0" dyntype="none" gaintype="fixed" biastype="none" dynprm="1 0 0" gainprm="1 0 0" biasprm="0 0 0" name="right_hip_z_107" />
    <general joint="right_hip_y_33" ctrllimited="true" forcelimited="false" ctrlrange="-0.4 0.4" forcerange="0 0" lengthrange="0 0" gear="300 0 0 0 0 0" dyntype="none" gaintype="fixed" biastype="none" dynprm="1 0 0" gainprm="1 0 0" biasprm="0 0 0" name="right_hip_y_108" />
    <general joint="right_hip_y_81" ctrllimited="true" forcelimited="false" ctrlrange="-0.4 0.4" forcerange="0 0" lengthrange="0 0" gear="300 0 0 0 0 0" dyntype="none" gaintype="fixed" biastype="none" dynprm="1 0 0" gainprm="1 0 0" biasprm="0 0 0" name="right_hip_y_109" />
    <general joint="right_knee_41" ctrllimited="true" forcelimited="false" ctrlrange="-0.4 0.4" forcerange="0 0" lengthrange="0 0" gear="200 0 0 0 0 0" dyntype="none" gaintype="fixed" biastype="none" dynprm="1 0 0" gainprm="1 0 0" biasprm="0 0 0" name="right_knee_110" />
    <general joint="right_knee_89" ctrllimited="true" forcelimited="false" ctrlrange="-0.4 0.4" forcerange="0 0" lengthrange="0 0" gear="200 0 0 0 0 0" dyntype="none" gaintype="fixed" biastype="none" dynprm="1 0 0" gainprm="1 0 0" biasprm="0 0 0" name="right_knee_111" />
    <general joint="left_hip_x_36" ctrllimited="true" forcelimited="false" ctrlrange="-0.4 0.4" forcerange="0 0" lengthrange="0 0" gear="100 0 0 0 0 0" dyntype="none" gaintype="fixed" biastype="none" dynprm="1 0 0" gainprm="1 0 0" biasprm="0 0 0" name="left_hip_x_112" />
    <general joint="left_hip_x_84" ctrllimited="true" forcelimited="false" ctrlrange="-0.4 0.4" forcerange="0 0" lengthrange="0 0" gear="100 0 0 0 0 0" dyntype="none" gaintype="fixed" biastype="none" dynprm="1 0 0" gainprm="1 0 0" biasprm="0 0 0" name="left_hip_x_113" />
    <general joint="left_hip_z_37" ctrllimited="true" forcelimited="false" ctrlrange="-0.4 0.4" forcerange="0 0" lengthrange="0 0" gear="100 0 0 0 0 0" dyntype="none" gaintype="fixed" biastype="none" dynprm="1 0 0" gainprm="1 0 0" biasprm="0 0 0" name="left_hip_z_114" />
    <general joint="left_hip_z_85" ctrllimited="true" forcelimited="false" ctrlrange="-0.4 0.4" forcerange="0 0" lengthrange="0 0" gear="100 0 0 0 0 0" dyntype="none" gaintype="fixed" biastype="none" dynprm="1 0 0" gainprm="1 0 0" biasprm="0 0 0" name="left_hip_z_115" />
    <general joint="left_hip_y_38" ctrllimited="true" forcelimited="false" ctrlrange="-0.4 0.4" forcerange="0 0" lengthrange="0 0" gear="300 0 0 0 0 0" dyntype="none" gaintype="fixed" biastype="none" dynprm="1 0 0" gainprm="1 0 0" biasprm="0 0 0" name="left_hip_y_116" />
    <general joint="left_hip_y_86" ctrllimited="true" forcelimited="false" ctrlrange="-0.4 0.4" forcerange="0 0" lengthrange="0 0" gear="300 0 0 0 0 0" dyntype="none" gaintype="fixed" biastype="none" dynprm="1 0 0" gainprm="1 0 0" biasprm="0 0 0" name="left_hip_y_117" />
    <general joint="left_knee_44" ctrllimited="true" forcelimited="false" ctrlrange="-0.4 0.4" forcerange="0 0" lengthrange="0 0" gear="200 0 0 0 0 0" dyntype="none" gaintype="fixed" biastype="none" dynprm="1 0 0" gainprm="1 0 0" biasprm="0 0 0" name="left_knee_118" />
    <general joint="left_knee_92" ctrllimited="true" forcelimited="false" ctrlrange="-0.4 0.4" forcerange="0 0" lengthrange="0 0" gear="200 0 0 0 0 0" dyntype="none" gaintype="fixed" biastype="none" dynprm="1 0 0" gainprm="1 0 0" biasprm="0 0 0" name="left_knee_119" />
    <general joint="right_shoulder1_13" ctrllimited="true" forcelimited="false" ctrlrange="-0.4 0.4" forcerange="0 0" lengthrange="0 0" gear="25 0 0 0 0 0" dyntype="none" gaintype="fixed" biastype="none" dynprm="1 0 0" gainprm="1 0 0" biasprm="0 0 0" name="right_shoulder1_120" />
    <general joint="right_shoulder1_61" ctrllimited="true" forcelimited="false" ctrlrange="-0.4 0.4" forcerange="0 0" lengthrange="0 0" gear="25 0 0 0 0 0" dyntype="none" gaintype="fixed" biastype="none" dynprm="1 0 0" gainprm="1 0 0" biasprm="0 0 0" name="right_shoulder1_121" />
    <general joint="right_shoulder2_14" ctrllimited="true" forcelimited="false" ctrlrange="-0.4 0.4" forcerange="0 0" lengthrange="0 0" gear="25 0 0 0 0 0" dyntype="none" gaintype="fixed" biastype="none" dynprm="1 0 0" gainprm="1 0 0" biasprm="0 0 0" name="right_shoulder2_122" />
    <general joint="right_shoulder2_62" ctrllimited="true" forcelimited="false" ctrlrange="-0.4 0.4" forcerange="0 0" lengthrange="0 0" gear="25 0 0 0 0 0" dyntype="none" gaintype="fixed" biastype="none" dynprm="1 0 0" gainprm="1 0 0" biasprm="0 0 0" name="right_shoulder2_123" />
    <general joint="right_elbow_25" ctrllimited="true" forcelimited="false" ctrlrange="-0.4 0.4" forcerange="0 0" lengthrange="0 0" gear="25 0 0 0 0 0" dyntype="none" gaintype="fixed" biastype="none" dynprm="1 0 0" gainprm="1 0 0" biasprm="0 0 0" name="right_elbow_124" />
    <general joint="right_elbow_73" ctrllimited="true" forcelimited="false" ctrlrange="-0.4 0.4" forcerange="0 0" lengthrange="0 0" gear="25 0 0 0 0 0" dyntype="none" gaintype="fixed" biastype="none" dynprm="1 0 0" gainprm="1 0 0" biasprm="0 0 0" name="right_elbow_125" />
    <general joint="left_shoulder1_17" ctrllimited="true" forcelimited="false" ctrlrange="-0.4 0.4" forcerange="0 0" lengthrange="0 0" gear="25 0 0 0 0 0" dyntype="none" gaintype="fixed" biastype="none" dynprm="1 0 0" gainprm="1 0 0" biasprm="0 0 0" name="left_shoulder1_126" />
    <general joint="left_shoulder1_65" ctrllimited="true" forcelimited="false" ctrlrange="-0.4 0.4" forcerange="0 0" lengthrange="0 0" gear="25 0 0 0 0 0" dyntype="none" gaintype="fixed" biastype="none" dynprm="1 0 0" gainprm="1 0 0" biasprm="0 0 0" name="left_shoulder1_127" />
    <general joint="left_shoulder2_18" ctrllimited="true" forcelimited="false" ctrlrange="-0.4 0.4" forcerange="0 0" lengthrange="0 0" gear="25 0 0 0 0 0" dyntype="none" gaintype="fixed" biastype="none" dynprm="1 0 0" gainprm="1 0 0" biasprm="0 0 0" name="left_shoulder2_128" />
    <general joint="left_shoulder2_66" ctrllimited="true" forcelimited="false" ctrlrange="-0.4 0.4" forcerange="0 0" lengthrange="0 0" gear="25 0 0 0 0 0" dyntype="none" gaintype="fixed" biastype="none" dynprm="1 0 0" gainprm="1 0 0" biasprm="0 0 0" name="left_shoulder2_129" />
    <general joint="left_elbow_28" ctrllimited="true" forcelimited="false" ctrlrange="-0.4 0.4" forcerange="0 0" lengthrange="0 0" gear="25 0 0 0 0 0" dyntype="none" gaintype="fixed" biastype="none" dynprm="1 0 0" gainprm="1 0 0" biasprm="0 0 0" name="left_elbow_130" />
    <general joint="left_elbow_76" ctrllimited="true" forcelimited="false" ctrlrange="-0.4 0.4" forcerange="0 0" lengthrange="0 0" gear="25 0 0 0 0 0" dyntype="none" gaintype="fixed" biastype="none" dynprm="1 0 0" gainprm="1 0 0" biasprm="0 0 0" name="left_elbow_131" />
  </actuator>
  <sensor />
  <compiler coordinate="local" />
  <option gravity="0 0 -9.81" timestep="0.02" />
  <option impratio="1" magnetic="0 0 0" wind="0 0 0" density="0" viscosity="0" o_margin="0" o_solref="0.02 1" o_solimp="0.9 0.95 0.001 0.5 2" integrator="Euler" cone="pyramidal" jacobian="auto" solver="Newton" iterations="8" tolerance="1E-08" noslip_iterations="0" noslip_tolerance="1E-06" mpr_iterations="50" mpr_tolerance="1E-06">
    <flag constraint="enable" equality="enable" frictionloss="enable" limit="enable" contact="enable" passive="enable" gravity="enable" clampctrl="enable" warmstart="enable" filterparent="enable" actuation="enable" refsafe="enable" override="disable" energy="disable" fwdinv="disable" sensornoise="disable" multiccd="disable" />
  </option>
  <size memory="-1" />
  <custom>
    <numeric name="constraint_limit_stiffness" data="2500" />
    <numeric name="constraint_stiffness" data="27000" />
    <numeric name="constraint_ang_damping" data="30" />
    <numeric name="constraint_vel_damping" data="80" />
    <numeric name="ang_damping" data="-0.05" />
    <numeric name="joint_scale_pos" data="0.5" />
    <numeric name="joint_scale_ang" data="0.1" />
    <numeric name="spring_mass_scale" data="0" />
    <numeric name="spring_inertia_scale" data="1" />
    <numeric name="matrix_inv_iterations" data="20" />
    <numeric name="solver_maxls" data="15" />
  </custom>
  <asset />
  <visual>
        <map fogend="5" fogstart="3"/>
  </visual>
  <asset>
        <texture builtin="gradient" height="100" rgb1=".4 .5 .6" rgb2="0 0 0" type="skybox" width="100"/>
        <!-- <texture builtin="gradient" height="100" rgb1="1 1 1" rgb2="0 0 0" type="skybox" width="100"/>-->
        <texture builtin="flat" height="1278" mark="cross" markrgb="1 1 1" name="texgeom" random="0.01" rgb1="0.8 0.6 0.4" rgb2="0.8 0.6 0.4" type="cube" width="127"/>
        <texture builtin="checker" height="100" name="texplane" rgb1="0 0 0" rgb2="0.8 0.8 0.8" type="2d" width="100"/>
        <material name="MatPlane" reflectance="0.5" shininess="1" specular="1" texrepeat="60 60" texture="texplane"/>
        <material name="geom" texture="texgeom" texuniform="true"/>
  </asset>
</mujoco>
