<mujoco model="point_mass">
  <compiler angle="degree" coordinate="local" inertiafromgeom="true"/>
  <option timestep="0.02" iterations="4"/>
  <custom>
    <!-- brax custom params -->
    <!-- <numeric data="0.0 0.0 0.55 1.0 0.0 0.0 0.0 0.0 1.0 0.0 -1.0 0.0 -1.0 0.0 1.0 1.0 0.0 0.55 1.0 0.0 0.0 0.0 0.0 1.0 0.0 -1.0 0.0 -1.0 0.0 1.0" name="init_qpos"/> -->
    <numeric data="0.0 0.0 1.0 1.0" name="init_qpos"/>
    <numeric data="1000" name="constraint_limit_stiffness"/>
    <numeric data="4000" name="constraint_stiffness"/>
    <numeric data="10" name="constraint_ang_damping"/>
    <numeric data="20" name="constraint_vel_damping"/>
    <numeric data="0.5" name="joint_scale_pos"/>
    <numeric data="0.2" name="joint_scale_ang"/>
    <numeric data="0.0" name="ang_damping"/>
    <numeric data="1" name="spring_mass_scale"/>
    <numeric data="1" name="spring_inertia_scale"/>
    <numeric data="15" name="solver_maxls"/>
  </custom>

  <default>
    <joint armature="0" damping="0" limited="true"/>
    <geom contype="1" friction="1 0.1 0.1" rgba="0.8 0.6 0.4 1"/>
  </default>

  <asset>
    <!-- <texture builtin="flat" height="100" rgb1="0.8 0.6 0.4" rgb2="0.8 0.6 0.4" type="2" width="100"/> -->
    <texture builtin="gradient" height="100" rgb1="1 1 1" rgb2="0 0 0" type="skybox" width="100"/>
    <texture builtin="flat" height="1278" mark="cross" markrgb="1 1 1" name="texgeom" random="0.01" rgb1="0.8 0.6 0.4" rgb2="0.8 0.6 0.4" type="cube" width="127"/>
    <texture builtin="checker" height="100" name="texplane" rgb1="0 0 0" rgb2="0.8 0.8 0.8" type="2d" width="100"/>
    <material name="MatPlane" reflectance="0.5" shininess="1" specular="1" texrepeat="60 60" texture="texplane"/>
    <material name="geom" texture="texgeom" texuniform="true"/>
    <material name="grey" reflectance="0.5"/>
  </asset>

  <worldbody>
    <light cutoff="100" diffuse="1 1 1" dir="-0 0 -1.3" directional="true" exponent="1" pos="0 0 1.3" specular=".1 .1 .1"/>
    <geom conaffinity="1" condim="3" material="MatPlane" name="floor" pos="0 0 0" size="40 40 40" type="plane" rgba="0.5 0.5 0.5 1.0"/>
    <body name="point_mass_a1" pos="0 0 0.256">
      <geom name="pointmass_a_1" type="sphere" size=".25"/>
      <joint name="root_x_a_1" type="slide" pos="0 0 0" axis="1 0 0" range="-100 100"/>
      <joint name="root_y_a_1" type="slide" pos="0 0 0" axis="0 1 0" range="-100 100"/>
    </body>
    <body name="point_mass_a2" pos="1 0 0.256">
      <geom name="pointmass_a_2" type="sphere" size=".25"/>
      <joint name="root_x_a_2" type="slide" pos="0 0 0" axis="1 0 0" range="-100 100"/>
      <joint name="root_y_a_2" type="slide" pos="0 0 0" axis="0 1 0" range="-100 100"/>
    </body>
  </worldbody>

  <actuator>
    <motor name="force_x_a1" joint="root_x_a_1" gear="20"/>
    <motor name="force_y_a1" joint="root_y_a_1" gear="20"/>
    <motor name="force_x_a2" joint="root_x_a_2" gear="0"/>
    <motor name="force_y_a2" joint="root_y_a_2" gear="0"/>
  </actuator>

</mujoco>
