<mujoco model="point_mass">
  <compiler angle="degree" coordinate="local" inertiafromgeom="true"/>
  <option timestep="0.02" iterations="4"/>
  <custom>
    <!-- brax custom params -->
    <!-- <numeric data="0.0 0.0 0.55 1.0 0.0 0.0 0.0 0.0 1.0 0.0 -1.0 0.0 -1.0 0.0 1.0 1.0 0.0 0.55 1.0 0.0 0.0 0.0 0.0 1.0 0.0 -1.0 0.0 -1.0 0.0 1.0" name="init_qpos"/> -->
    <!-- <numeric data="0.0 0.0 1.0 1.0" name="init_qpos"/> -->
    <numeric data="1000" name="constraint_limit_stiffness"/>
    <numeric data="4000" name="constraint_stiffness"/>
    <numeric data="10" name="constraint_ang_damping"/>
    <numeric data="20" name="constraint_vel_damping"/>
    <numeric data="0.5" name="joint_scale_pos"/>
    <numeric data="0.2" name="joint_scale_ang"/>
    <numeric data="0.0" name="ang_damping"/>
    <numeric data="1" name="spring_mass_scale"/>
    <numeric data="1" name="spring_inertia_scale"/>
    <numeric data="15" name="solver_maxls"/>
  </custom>

  <default>
    <joint armature="1" damping="1" limited="true"/>
    <geom contype="0" conaffinity="0" condim="3" density="5.0" friction="1 0.5 0.5"
     rgba="0.5 0.5 0.5 1"/>
  </default>

  <asset>
    <!-- <texture builtin="flat" height="100" rgb1="0.8 0.6 0.4" rgb2="0.8 0.6 0.4" type="2" width="100"/> -->
    <texture builtin="gradient" height="100" rgb1="1 1 1" rgb2="0 0 0" type="skybox" width="100"/>
    <texture builtin="flat" height="1278" mark="cross" markrgb="1 1 1" name="texgeom" random="0.01" rgb1="0.8 0.6 0.4" rgb2="0.8 0.6 0.4" type="cube" width="127"/>
    <texture builtin="checker" height="100" name="texplane" rgb1="0 0 0" rgb2="0.8 0.8 0.8" type="2d" width="100"/>
    <material name="MatPlane" reflectance="0.5" shininess="1" specular="1" texrepeat="60 60" texture="texplane"/>
    <material name="geom" texture="texgeom" texuniform="true"/>
    <material name="grey" reflectance="0.5"/>
  </asset>

  <worldbody>
    <light cutoff="100" diffuse="1 1 1" dir="-0 0 -1.3" directional="true" exponent="1" pos="0 0 1.3" specular=".1 .1 .1"/>
    <geom conaffinity="1" condim="3" material="MatPlane" name="floor" pos="0 0 0" size="40 40 40" type="plane" rgba="0.5 0.5 0.5 1.0" friction="1 .1 .1"/>
    <body name="torso_a_1" pos="0 0 0.5" >
            <joint armature="0" damping="0" limited="false" margin="0.01" name="root_a1" pos="0 0 0" type="free"/>
            <geom name="torso_geom_a1" type="box" size="0.2 0.2 0.1" rgba="0.0 1.0 0.0 1" contype="2" conaffinity="0"/>
            <body name="limb1_a_1" pos="0.25 0.25 -0.2">
                <joint name="joint1_a1" type="hinge" pos="0 0 0" axis="1 0 0" range="-50 50"/>
                <geom name="limb1_geom_a_1" type="capsule" size="0.1 0.1" rgba="0.5 0.5 0.5 1"  contype="1"/>
            </body>
            <body name="limb2_a_1" pos="0.25 -0.25 -0.2">
                <joint name="joint2_a1" type="hinge" pos="0 0 0" axis="0 1 0" range="-50 50"/>
                <geom name="limb2_geom_a_1" type="capsule" size="0.1 0.1" rgba="0.5 0.5 0.5 1"  contype="1"/>
            </body>
            <body name="limb3_a_1" pos="-0.25 0.25 -0.2">
                <joint name="joint3_a1" type="hinge" pos="0.0 0 0" axis="0 1 0" range="-50 50"/>
                <geom name="limb3_geom_a_1" type="capsule" size="0.1 0.1" rgba="0.5 0.5 0.5 1"  contype="1"/>
            </body>
            <body name="limb4_a_1" pos="-0.25 -0.25 -0.2">
                <joint name="joint4_a1" type="hinge" pos="0.1 0 0" axis="1 0 0" range="-50 50"/>
                <geom name="limb4_geom_a_1" type="capsule" size="0.1 0.1" rgba="0.5 0.5 0.5 1" contype="1"/>
            </body>
    </body>
    <body name="torso_a_2" pos="1.0 0 0.5" >
            <joint armature="0" damping="0" limited="false" margin="0.01" name="root_a2" pos="0 0 0" type="free"/>
            <geom name="torso_geom_a2" type="box" size="0.2 0.2 0.1" rgba="0.0 0.0 1.0 1" contype="2" conaffinity="0"/>
            <body name="limb1_a_2" pos="0.25 0.25 -0.2">
                <joint name="joint1_a2" type="hinge" pos="0 0 0" axis="1 0 0" range="-50 50"/>
                <geom name="limb1_geom_a_2" type="capsule" size="0.1 0.1" rgba="0.5 0.5 0.5 1"  contype="1"/>
            </body>
            <body name="limb2_a_2" pos="0.25 -0.25 -0.2">
                <joint name="joint2_a2" type="hinge" pos="0 0 0" axis="0 1 0" range="-50 50"/>
                <geom name="limb2_geom_a_2" type="capsule" size="0.1 0.1" rgba="0.5 0.5 0.5 1"  contype="1"/>
            </body>
            <body name="limb3_a_2" pos="-0.25 0.25 -0.2">
                <joint name="joint3_a2" type="hinge" pos="0.0 0 0" axis="0 1 0" range="-50 50"/>
                <geom name="limb3_geom_a_2" type="capsule" size="0.1 0.1" rgba="0.5 0.5 0.5 1"  contype="1"/>
            </body>
            <body name="limb4_a_2" pos="-0.25 -0.25 -0.2">
                <joint name="joint4_a2" type="hinge" pos="0.1 0 0" axis="1 0 0" range="-50 50"/>
                <geom name="limb4_geom_a_2" type="capsule" size="0.1 0.1" rgba="0.5 0.5 0.5 1" contype="1"/>
            </body>
    </body>
    <geom conaffinity="2" condim="3" name="wall_1" type="box" size="0.1 5 1" pos="5 0 1"/>
    <geom conaffinity="2" condim="3" name="wall_2" type="box" size="0.1 5 1" pos="0 5 1" quat="0.7071 0 0 0.7071"/>
    <geom conaffinity="2" condim="3" name="wall_3" type="box" size="0.1 5 1" pos="0 -5 1" quat="0.7071 0 0 0.7071"/>
    <geom conaffinity="2" condim="3" name="wall_4" type="box" size="0.1 5 1" pos="-5 0 1"/>
  </worldbody>

  <actuator>
    <motor ctrllimited="true" ctrlrange="-1.0 1.0" joint="joint1_a1" gear="10"/>
    <motor ctrllimited="true" ctrlrange="-1.0 1.0" joint="joint2_a1" gear="10"/>
    <motor ctrllimited="true" ctrlrange="-1.0 1.0" joint="joint3_a1" gear="10"/>
    <motor ctrllimited="true" ctrlrange="-1.0 1.0" joint="joint4_a1" gear="10"/>
    <motor ctrllimited="true" ctrlrange="-1.0 1.0" joint="joint1_a2" gear="10"/>
    <motor ctrllimited="true" ctrlrange="-1.0 1.0" joint="joint2_a2" gear="10"/>
    <motor ctrllimited="true" ctrlrange="-1.0 1.0" joint="joint3_a2" gear="10"/>
    <motor ctrllimited="true" ctrlrange="-1.0 1.0" joint="joint4_a2" gear="10"/>
  </actuator>

</mujoco>
