<mujoco model="linked_balls">
  <compiler angle="degree" coordinate="local" inertiafromgeom="true"/>
  <option timestep="0.01" iterations="4"/>
  <custom>
    <!-- brax custom params -->
    <!-- <numeric data="0.0 0.0 0.55 1.0 0.0 0.0 0.0 0.0 1.0 0.0 -1.0 0.0 -1.0 0.0 1.0 1.0 0.0 0.55 1.0 0.0 0.0 0.0 0.0 1.0 0.0 -1.0 0.0 -1.0 0.0 1.0" name="init_qpos"/> -->
    <!-- <numeric data="0.0 0.0 1.0 1.0" name="init_qpos"/> -->
    <!-- <numeric data="0.0 0.0 0.55 1.0 0.0 0.0 0.0 1.0 -1.0 -1.0 -1.0" name="init_qpos"/> -->
    <numeric data="1000" name="constraint_limit_stiffness"/>
    <numeric data="4000" name="constraint_stiffness"/>
    <numeric data="10" name="constraint_ang_damping"/>
    <numeric data="20" name="constraint_vel_damping"/>
    <numeric data="0.5" name="joint_scale_pos"/>
    <numeric data="0.2" name="joint_scale_ang"/>
    <numeric data="0.0" name="ang_damping"/>
    <numeric data="1" name="spring_mass_scale"/>
    <numeric data="1" name="spring_inertia_scale"/>
    <numeric data="15" name="solver_maxls"/>
  </custom>

  <default>
    <joint armature="1" damping="1" limited="true"/>
    <!-- <geom contype="1" friction="1 0.1 0.1" rgba="0.8 0.6 0.4 1"/> -->
  </default>

  <asset>
    <!-- <texture builtin="flat" height="100" rgb1="0.8 0.6 0.4" rgb2="0.8 0.6 0.4" type="2" width="100"/> -->
    <texture builtin="gradient" height="100" rgb1="1 1 1" rgb2="0 0 0" type="skybox" width="100"/>
    <texture builtin="flat" height="1278" mark="cross" markrgb="1 1 1" name="texgeom" random="0.01" rgb1="0.8 0.6 0.4" rgb2="0.8 0.6 0.4" type="cube" width="127"/>
    <texture builtin="checker" height="100" name="texplane" rgb1="0 0 0" rgb2="0.8 0.8 0.8" type="2d" width="100"/>
    <material name="MatPlane" reflectance="0.5" shininess="1" specular="1" texrepeat="60 60" texture="texplane"/>
    <material name="geom" texture="texgeom" texuniform="true"/>
    <material name="grey" reflectance="0.5"/>
  </asset>

  <worldbody>
    <light cutoff="100" diffuse="1 1 1" dir="-0 0 -1.3" directional="true" exponent="1" pos="0 0 1.3" specular=".1 .1 .1"/>
    <geom conaffinity="1" condim="3" material="MatPlane" name="floor" pos="0 0 0" size="40 40 40" type="plane" rgba="0.5 0.5 0.5 1.0"/>
    <body name="torso" pos="0 0 0.5" >
            <joint armature="0" damping="0" limited="false" margin="0.01" name="root" pos="0 0 0" type="free"/>
            <!-- <joint name="root_x_a_1" type="slide" pos="0 0 0" axis="1 0 0" range="-100 100"/>
            <joint name="root_y_a_1" type="slide" pos="0 0 0" axis="0 1 0" range="-100 100"/> -->
            <geom name="torso_geom" type="box" size="0.2 0.2 0.1" rgba="0.5 0.5 0.5 1" contype="0" conaffinity="0"/>
            <!-- Limb 1 -->
            <body name="limb1" pos="0.25 0.25 -0.2">
                <joint name="joint1" type="hinge" pos="0 0 0" range="-50 50"/>
                <geom name="limb1_geom" type="capsule" size="0.1 0.1" rgba="0.8 0.2 0.2 1"/>
            </body>
            <!-- Limb 2 -->
            <body name="limb2" pos="0.25 -0.25 -0.2">
                <joint name="joint2" type="hinge" pos="0 0 0" axis="1 0 0" range="-50 50"/>
                <geom name="limb2_geom" type="capsule" size="0.1 0.1" rgba="0.8 0.2 0.2 1"/>
            </body>
            <!-- Limb 3 -->
            <body name="limb3" pos="-0.25 0.25 -0.2">
                <joint name="joint3" type="hinge" pos="0.0 0 0" axis="1 0 0" range="-50 50"/>
                <geom name="limb3_geom" type="capsule" size="0.1 0.1" rgba="0.8 0.2 0.2 1"/>
            </body>
            <!-- Limb 4 -->
            <body name="limb4" pos="-0.25 -0.25 -0.2">
                <joint name="joint4" type="hinge" pos="0.1 0 0" axis="1 0 0" range="-50 50"/>
                <geom name="limb4_geom" type="capsule" size="0.1 0.1" rgba="0.8 0.2 0.2 1"/>
            </body>
    </body>
    <geom conaffinity="2" condim="3" name="wall_1" type="box" size="0.1 5 1" pos="5 0 1"/>
    <geom conaffinity="2" condim="3" name="wall_2" type="box" size="0.1 5 1" pos="0 5 1" quat="0.7071 0 0 0.7071"/>
    <geom conaffinity="2" condim="3" name="wall_3" type="box" size="0.1 5 1" pos="0 -5 1" quat="0.7071 0 0 0.7071"/>
    <geom conaffinity="2" condim="3" name="wall_4" type="box" size="0.1 5 1" pos="-5 0 1"/>
  </worldbody>

  <actuator>

    <motor ctrllimited="true" ctrlrange="-1.0 1.0" joint="joint1" gear="10"/>
    <motor ctrllimited="true" ctrlrange="-1.0 1.0" joint="joint2" gear="10"/>
    <motor ctrllimited="true" ctrlrange="-1.0 1.0" joint="joint3" gear="10"/>
    <motor ctrllimited="true" ctrlrange="-1.0 1.0" joint="joint4" gear="10"/>


    <!-- <motor ctrllimited="true" ctrlrange="-1.0 1.0" joint="joint1" gear="10"/>
    <motor ctrllimited="true" ctrlrange="-1.0 1.0" joint="joint2" gear="10"/>
    <motor ctrllimited="true" ctrlrange="-1.0 1.0" joint="joint3" gear="10"/>
    <motor ctrllimited="true" ctrlrange="-1.0 1.0" joint="joint4" gear="10"/> -->


    <!-- <motor ctrllimited="true" ctrlrange="-1.0 1.0" joint="hip_1" gear="10"/>
    <motor ctrllimited="true" ctrlrange="-1.0 1.0" joint="hip_2" gear="10"/>
    <motor ctrllimited="true" ctrlrange="-1.0 1.0" joint="hip_3" gear="10"/>
    <motor ctrllimited="true" ctrlrange="-1.0 1.0" joint="hip_4" gear="10"/> -->


    <!-- <motor ctrllimited="true" ctrlrange="-1.0 1.0" joint="ankle_1" gear="10"/> -->
    <!-- <motor name="force_x_a1" joint="root_x_a_1" gear="10"/> -->
    <!-- <motor name="force_y_a1" joint="root_y_a_1" gear="10"/> -->
    <!-- <motor name="force_x_a2" joint="root_x_a_2" gear="10"/>
    <motor name="force_y_a2" joint="root_y_a_2" gear="10"/>
    <motor name="force_x_a1_1" joint="root_x_a_1_1" gear="10"/>
    <motor name="force_y_a1_1" joint="root_y_a_1_1" gear="10"/>
    <motor name="force_x_a2_1" joint="root_x_a_2_1" gear="10"/>
    <motor name="force_y_a2_1" joint="root_y_a_2_1" gear="10"/> -->
  </actuator>

</mujoco>
